[2025-03-30T02:20:15.295+0000] {taskinstance.py:1159} INFO - Dependencies all met for dep_context=non-requeueable deps ti=<TaskInstance: kafka_spark_dag.pyspark_consumer scheduled__2025-03-30T02:10:00+00:00 [queued]>
[2025-03-30T02:20:15.307+0000] {taskinstance.py:1159} INFO - Dependencies all met for dep_context=requeueable deps ti=<TaskInstance: kafka_spark_dag.pyspark_consumer scheduled__2025-03-30T02:10:00+00:00 [queued]>
[2025-03-30T02:20:15.308+0000] {taskinstance.py:1361} INFO - Starting attempt 2 of 2
[2025-03-30T02:20:15.326+0000] {taskinstance.py:1382} INFO - Executing <Task(DockerOperator): pyspark_consumer> on 2025-03-30 02:10:00+00:00
[2025-03-30T02:20:15.337+0000] {standard_task_runner.py:57} INFO - Started process 20291 to run task
[2025-03-30T02:20:15.340+0000] {standard_task_runner.py:84} INFO - Running: ['***', 'tasks', 'run', 'kafka_spark_dag', 'pyspark_consumer', 'scheduled__2025-03-30T02:10:00+00:00', '--job-id', '101', '--raw', '--subdir', 'DAGS_FOLDER/dag_kafka_spark.py', '--cfg-path', '/tmp/tmpyvz0_1hc']
[2025-03-30T02:20:15.344+0000] {standard_task_runner.py:85} INFO - Job 101: Subtask pyspark_consumer
[2025-03-30T02:20:15.406+0000] {task_command.py:416} INFO - Running <TaskInstance: kafka_spark_dag.pyspark_consumer scheduled__2025-03-30T02:10:00+00:00 [running]> on host a6934a850e84
[2025-03-30T02:20:15.497+0000] {taskinstance.py:1662} INFO - Exporting env vars: AIRFLOW_CTX_DAG_OWNER='***' AIRFLOW_CTX_DAG_ID='kafka_spark_dag' AIRFLOW_CTX_TASK_ID='pyspark_consumer' AIRFLOW_CTX_EXECUTION_DATE='2025-03-30T02:10:00+00:00' AIRFLOW_CTX_TRY_NUMBER='2' AIRFLOW_CTX_DAG_RUN_ID='scheduled__2025-03-30T02:10:00+00:00'
[2025-03-30T02:20:15.521+0000] {docker.py:470} INFO - Pulling docker image spotifystream-spark-server
[2025-03-30T02:20:19.608+0000] {taskinstance.py:1937} ERROR - Task failed with exception
Traceback (most recent call last):
  File "/home/airflow/.local/lib/python3.8/site-packages/docker/api/client.py", line 268, in _raise_for_status
    response.raise_for_status()
  File "/home/airflow/.local/lib/python3.8/site-packages/requests/models.py", line 1021, in raise_for_status
    raise HTTPError(http_error_msg, response=self)
requests.exceptions.HTTPError: 404 Client Error: Not Found for url: http://docker-proxy:2375/v1.48/images/create?tag=latest&fromImage=spotifystream-spark-server

The above exception was the direct cause of the following exception:

Traceback (most recent call last):
  File "/home/airflow/.local/lib/python3.8/site-packages/airflow/providers/docker/operators/docker.py", line 472, in execute
    for output in self.cli.pull(self.image, stream=True, decode=True):
  File "/home/airflow/.local/lib/python3.8/site-packages/docker/api/image.py", line 429, in pull
    self._raise_for_status(response)
  File "/home/airflow/.local/lib/python3.8/site-packages/docker/api/client.py", line 270, in _raise_for_status
    raise create_api_error_from_http_exception(e) from e
  File "/home/airflow/.local/lib/python3.8/site-packages/docker/errors.py", line 39, in create_api_error_from_http_exception
    raise cls(e, response=response, explanation=explanation) from e
docker.errors.ImageNotFound: 404 Client Error for http://docker-proxy:2375/v1.48/images/create?tag=latest&fromImage=spotifystream-spark-server: Not Found ("pull access denied for spotifystream-spark-server, repository does not exist or may require 'docker login': denied: requested access to the resource is denied")
[2025-03-30T02:20:19.623+0000] {taskinstance.py:1400} INFO - Marking task as FAILED. dag_id=kafka_spark_dag, task_id=pyspark_consumer, execution_date=20250330T021000, start_date=20250330T022015, end_date=20250330T022019
[2025-03-30T02:20:19.638+0000] {standard_task_runner.py:104} ERROR - Failed to execute job 101 for task pyspark_consumer (404 Client Error for http://docker-proxy:2375/v1.48/images/create?tag=latest&fromImage=spotifystream-spark-server: Not Found ("pull access denied for spotifystream-spark-server, repository does not exist or may require 'docker login': denied: requested access to the resource is denied"); 20291)
[2025-03-30T02:20:19.695+0000] {local_task_job_runner.py:228} INFO - Task exited with return code 1
[2025-03-30T02:20:19.721+0000] {taskinstance.py:2778} INFO - 0 downstream tasks scheduled from follow-on schedule check
